<?xml version="1.0"?>
<robot xmlns:xacro="http://www.ros.org/wiki/xacro" >
    <xacro:include filename="inertial_macros.xacro"/>

   <material name="white">
        <color rgba="1 1 1 1" />
    </material>
    <material name="orange">
        <color rgba="1 0.3 0.1 1" />
    </material>
    <material name="blue">
        <color rgba="0.2 0.2 1 1" />
    </material>
    <material name="black">
        <color rgba="0 0 0 1" />
    </material>
    <!--BASE LINK-->
    <link name="base_link">

    </link>
    <!-- BASE FOOTPRINT LINK -->
    <joint name="base_footprint_joint" type="fixed">
        <parent link="base_link"/>
        <child link="base_footprint"/>
        <origin xyz="0 0 0" rpy="0 0 0"/>
    </joint>
    <link name="base_footprint">
    </link>
    <!--CHASSIS LINK-->
    <joint name="chassis_joint" type="fixed">
        <parent link="base_link"/>
        <child link="chassis"/>
        <origin xyz="-0.0975 0 0"/>  <!--ubicar el origen en la parte de atras-->
    </joint>

    <link name="chassis">
        <visual>
            <origin xyz="0.0975 0 0.075"/>
            <geometry>
                <box size="0.195 0.12 0.15"/>
            </geometry>
            <material name = "white"/>
        </visual>
        <collision>
            <origin xyz="0.0975 0 0.075"/>
            <geometry>
                <box size="0.195 0.12 0.15"/>
            </geometry>
        </collision>
        <xacro:inertial_box mass="0.5" x="0.195" y="0.12" z="0.15">
            <origin xyz="0.0975 0 0.075" rpy="0 0 0"/>
        </xacro:inertial_box>
    </link>
    <gazebo reference="chassis">
        <material>Gazebo/White</material>
    </gazebo>

    <!-- LEFT WHEELS-->
    <!--Center wheel-->
    <joint name="left_wheel_joint" type="continuous">
        <parent link="base_link"/>
        <child link="left_wheel"/>
        <origin xyz="0 0.085 0" rpy="-${pi/2} 0 0"/>
        <axis xyz="0 0 1"/>
    </joint>
    <link name="left_wheel">
        <visual>
            <geometry>
                <cylinder radius="0.02" length="0.04"/>
            </geometry>
            <material name="orange"/>
        </visual>
        <collision>
            <geometry>
                <cylinder radius="0.02" length="0.04"/>
            </geometry>
        </collision>
        <xacro:inertial_cylinder mass="0.1" length="0.04" radius="0.02">
            <origin xyz="0 0 0" rpy="0 0 0"/>
        </xacro:inertial_cylinder> 
    </link>
    <gazebo reference="left_wheel">
        <material>Gazebo/Red</material>
    </gazebo>
    <!--front wheel-->
    <joint name="front_left_wheel_joint" type="fixed">
        <parent link="base_link"/>
        <child link="front_left_wheel"/>
        <origin xyz="0.065 0.085 0" rpy="-${pi/2} 0 0"/>
        <axis xyz="0 0 1"/>
    </joint>
    <link name="front_left_wheel">
        <visual>
            <geometry>
                <cylinder radius="0.02" length="0.04"/>
            </geometry>
            <material name="orange"/>
        </visual>
        <collision>
            <geometry>
                <cylinder radius="0.02" length="0.04"/>
            </geometry>
        </collision>
        <xacro:inertial_cylinder mass="0.1" length="0.04" radius="0.02">
            <origin xyz="0 0 0" rpy="0 0 0"/>
        </xacro:inertial_cylinder> 
    </link>
    <gazebo reference="front_left_wheel">
        <material>Gazebo/Red</material>
    </gazebo>
    <!--back wheel-->
    <joint name="back_left_wheel_joint" type="fixed">
        <parent link="base_link"/>
        <child link="back_left_wheel"/>
        <origin xyz="-0.065 0.085 0" rpy="-${pi/2} 0 0"/>
        <axis xyz="0 0 1"/>
    </joint>
    <link name="back_left_wheel">
        <visual>
            <geometry>
                <cylinder radius="0.02" length="0.04"/>
            </geometry>
            <material name="orange"/>
        </visual>
        <collision>
            <geometry>
                <cylinder radius="0.02" length="0.04"/>
            </geometry>
        </collision>
        <xacro:inertial_cylinder mass="0.1" length="0.04" radius="0.02">
            <origin xyz="0 0 0" rpy="0 0 0"/>
        </xacro:inertial_cylinder> 
    </link>
    <gazebo reference="back_left_wheel">
        <material>Gazebo/Red</material>
    </gazebo>
    <!-- RIGHT WHEELS-->
    <!--Center wheel-->
    <joint name="right_wheel_joint" type="continuous">
        <parent link="base_link"/>
        <child link="right_wheel"/>
        <origin xyz="0 -0.085 0" rpy="${pi/2} 0 0"/>
        <axis xyz="0 0 -1"/>
    </joint>
    <link name="right_wheel">
        <visual>
            <geometry>
                <cylinder radius="0.02" length="0.04"/>
            </geometry>
            <material name="orange"/>
        </visual>
        <collision>
            <geometry>
                <cylinder radius="0.02" length="0.04"/>
            </geometry>
        </collision>
        <xacro:inertial_cylinder mass="0.1" length="0.04" radius="0.02">
            <origin xyz="0 0 0" rpy="0 0 0"/>
        </xacro:inertial_cylinder> 
    </link>
    <gazebo reference="right_wheel">
        <material>Gazebo/Red</material>
    </gazebo>
    <!--Front wheel-->
    <joint name="front_right_wheel_joint" type="fixed">
        <parent link="base_link"/>
        <child link="front_right_wheel"/>
        <origin xyz="0.065 -0.085 0" rpy="${pi/2} 0 0"/>
        <axis xyz="0 0 -1"/>
    </joint>
    <link name="front_right_wheel">
        <visual>
            <geometry>
                <cylinder radius="0.02" length="0.04"/>
            </geometry>
            <material name="orange"/>
        </visual>
        <collision>
            <geometry>
                <cylinder radius="0.02" length="0.04"/>
            </geometry>
        </collision>
        <xacro:inertial_cylinder mass="0.1" length="0.04" radius="0.02">
            <origin xyz="0 0 0" rpy="0 0 0"/>
        </xacro:inertial_cylinder> 
    </link>
    <gazebo reference="front_right_wheel">
        <material>Gazebo/Red</material>
    </gazebo>
    <!--back wheel-->
    <joint name="back_right_wheel_joint" type="fixed">
        <parent link="base_link"/>
        <child link="back_right_wheel"/>
        <origin xyz="-0.065 -0.085 0" rpy="${pi/2} 0 0"/>
        <axis xyz="0 0 -1"/>
    </joint>
    <link name="back_right_wheel">
        <visual>
            <geometry>
                <cylinder radius="0.02" length="0.04"/>
            </geometry>
            <material name="orange"/>
        </visual>
        <collision>
            <geometry>
                <cylinder radius="0.02" length="0.04"/>
            </geometry>
        </collision>
        <xacro:inertial_cylinder mass="0.1" length="0.04" radius="0.02">
            <origin xyz="0 0 0" rpy="0 0 0"/>
        </xacro:inertial_cylinder> 
    </link>
    <gazebo reference="back_right_wheel">
        <material>Gazebo/Red</material>
    </gazebo>

    <joint name = "laser_joint" type="fixed">
        <parent link = "chassis"/>
        <child link = "laser_frame"/>
        <origin xyz = "0.1 0 0.175" rpy="0 0 0" />
    </joint>

    <link name = "laser_frame">
        <visual>
            <geometry>
                <cylinder radius="0.05" length="0.04"/>
            </geometry>
            <material name="black"/>
        </visual>
        <visual>
            <origin xyz="0 0 -0.05"/>
            <geometry>
                <cylinder radius="0.01" length="0.1"/>
            </geometry>
            <material name="black"/>
        </visual>
        <collision>
            <geometry>
                <cylinder radius="0.05" length="0.04"/>
            </geometry>
        </collision>
        <xacro:inertial_cylinder mass="0.1" length="0.04" radius="0.05">
            <origin xyz="0 0 0" rpy="0 0 0"/>
        </xacro:inertial_cylinder>        
    </link>
</robot>